<?xml version="1.0" ?>
<!-- =================================================================================== -->
<!-- |    This document was autogenerated by xacro from /home/einig/catkin_ws/src/pmr_robot/pmr_description/robots/pmr_n_link.urdf.xacro | -->
<!-- |    EDITING THIS FILE BY HAND IS NOT RECOMMENDED                                 | -->
<!-- =================================================================================== -->
<robot name="pmr_robot" xmlns:xacro="http://www.ros.org/wiki/xacro">
  <!-- Set the count of desired modules. Naming will start at 0 to link_numer-1
	Maximum recursion depth of xacro in Indigo: 246-->
  <link name="base_link">
    <origin rpy="0 0 0" xyz="0 0 0"/>
  </link>
  <link name="arduino_link_0.0">
    <visual>
      <geometry>
        <mesh filename="package://pmr_description/meshes/moduleArduino.dae" scale="0.001 0.001 0.001"/>
      </geometry>
      <origin rpy="0 0 0" xyz="0 0 0.009"/>
    </visual>
  </link>
  <link name="servo_link_0.0">
    <visual>
      <geometry>
        <mesh filename="package://pmr_description/meshes/moduleServo.dae" scale="0.001 0.001 0.001"/>
      </geometry>
      <origin rpy="0 3.14159265359 0" xyz="0 0 0"/>
    </visual>
  </link>
  <link name="battery_link_0.0">
    <visual>
      <geometry>
        <mesh filename="package://pmr_description/meshes/moduleBattery.dae" scale="0.001 0.001 0.001"/>
      </geometry>
      <origin rpy="0 3.14159265359 0" xyz="0 0 0"/>
    </visual>
  </link>
  <link name="end_link_0.0">
    <origin rpy="0 0 0" xyz="0 0 0"/>
  </link>
  <joint name="base_joint_0.0" type="fixed">
    <parent link="base_link"/>
    <child link="arduino_link_0.0"/>
  </joint>
  <joint name="battery_joint_0.0" type="fixed">
    <parent link="servo_link_0.0"/>
    <child link="battery_link_0.0"/>
    <origin rpy="0 0 0" xyz="0 -0.0005 0.025"/>
  </joint>
  <joint name="end_joint_0.0" type="fixed">
    <parent link="battery_link_0.0"/>
    <child link="end_link_0.0"/>
    <origin rpy="0 0 0" xyz="-0.0007 0.002 0.016"/>
  </joint>
  <joint name="module_joint_0.0" type="revolute">
    <parent link="arduino_link_0.0"/>
    <child link="servo_link_0.0"/>
    <origin rpy="0 0 0" xyz="0.0005 -0.0003 0.041"/>
    <axis xyz="0 1 0"/>
    <limit effort="1" lower="-1.57079632679" upper="1.57079632679" velocity="1"/>
  </joint>
  <xacro:property name="parent_link" value="2"/>
  <link name="arduino_link_1.0">
    <visual>
      <geometry>
        <mesh filename="package://pmr_description/meshes/moduleArduino.dae" scale="0.001 0.001 0.001"/>
      </geometry>
      <origin rpy="0 0 0" xyz="0 0 0.009"/>
    </visual>
  </link>
  <link name="servo_link_1.0">
    <visual>
      <geometry>
        <mesh filename="package://pmr_description/meshes/moduleServo.dae" scale="0.001 0.001 0.001"/>
      </geometry>
      <origin rpy="0 3.14159265359 0" xyz="0 0 0"/>
    </visual>
  </link>
  <link name="battery_link_1.0">
    <visual>
      <geometry>
        <mesh filename="package://pmr_description/meshes/moduleBattery.dae" scale="0.001 0.001 0.001"/>
      </geometry>
      <origin rpy="0 3.14159265359 0" xyz="0 0 0"/>
    </visual>
  </link>
  <link name="end_link_1.0">
    <origin rpy="0 0 0" xyz="0 0 0"/>
  </link>
  <joint name="base_joint_1.0" type="fixed">
    <parent link="end_link_0.0"/>
    <child link="arduino_link_1.0"/>
  </joint>
  <joint name="battery_joint_1.0" type="fixed">
    <parent link="servo_link_1.0"/>
    <child link="battery_link_1.0"/>
    <origin rpy="0 0 0" xyz="0 -0.0005 0.025"/>
  </joint>
  <joint name="end_joint_1.0" type="fixed">
    <parent link="battery_link_1.0"/>
    <child link="end_link_1.0"/>
    <origin rpy="0 0 0" xyz="-0.0007 0.002 0.016"/>
  </joint>
  <joint name="module_joint_1.0" type="revolute">
    <parent link="arduino_link_1.0"/>
    <child link="servo_link_1.0"/>
    <origin rpy="0 0 0" xyz="0.0005 -0.0003 0.041"/>
    <axis xyz="0 1 0"/>
    <limit effort="1" lower="-1.57079632679" upper="1.57079632679" velocity="1"/>
  </joint>
  <xacro:property name="parent_link" value="2"/>
  <link name="arduino_link_2.0">
    <visual>
      <geometry>
        <mesh filename="package://pmr_description/meshes/moduleArduino.dae" scale="0.001 0.001 0.001"/>
      </geometry>
      <origin rpy="0 0 0" xyz="0 0 0.009"/>
    </visual>
  </link>
  <link name="servo_link_2.0">
    <visual>
      <geometry>
        <mesh filename="package://pmr_description/meshes/moduleServo.dae" scale="0.001 0.001 0.001"/>
      </geometry>
      <origin rpy="0 3.14159265359 0" xyz="0 0 0"/>
    </visual>
  </link>
  <link name="battery_link_2.0">
    <visual>
      <geometry>
        <mesh filename="package://pmr_description/meshes/moduleBattery.dae" scale="0.001 0.001 0.001"/>
      </geometry>
      <origin rpy="0 3.14159265359 0" xyz="0 0 0"/>
    </visual>
  </link>
  <link name="end_link_2.0">
    <origin rpy="0 0 0" xyz="0 0 0"/>
  </link>
  <joint name="base_joint_2.0" type="fixed">
    <parent link="end_link_1.0"/>
    <child link="arduino_link_2.0"/>
  </joint>
  <joint name="battery_joint_2.0" type="fixed">
    <parent link="servo_link_2.0"/>
    <child link="battery_link_2.0"/>
    <origin rpy="0 0 0" xyz="0 -0.0005 0.025"/>
  </joint>
  <joint name="end_joint_2.0" type="fixed">
    <parent link="battery_link_2.0"/>
    <child link="end_link_2.0"/>
    <origin rpy="0 0 0" xyz="-0.0007 0.002 0.016"/>
  </joint>
  <joint name="module_joint_2.0" type="revolute">
    <parent link="arduino_link_2.0"/>
    <child link="servo_link_2.0"/>
    <origin rpy="0 0 0" xyz="0.0005 -0.0003 0.041"/>
    <axis xyz="0 1 0"/>
    <limit effort="1" lower="-1.57079632679" upper="1.57079632679" velocity="1"/>
  </joint>
  <xacro:property name="parent_link" value="2"/>
  <link name="arduino_link_3.0">
    <visual>
      <geometry>
        <mesh filename="package://pmr_description/meshes/moduleArduino.dae" scale="0.001 0.001 0.001"/>
      </geometry>
      <origin rpy="0 0 0" xyz="0 0 0.009"/>
    </visual>
  </link>
  <link name="servo_link_3.0">
    <visual>
      <geometry>
        <mesh filename="package://pmr_description/meshes/moduleServo.dae" scale="0.001 0.001 0.001"/>
      </geometry>
      <origin rpy="0 3.14159265359 0" xyz="0 0 0"/>
    </visual>
  </link>
  <link name="battery_link_3.0">
    <visual>
      <geometry>
        <mesh filename="package://pmr_description/meshes/moduleBattery.dae" scale="0.001 0.001 0.001"/>
      </geometry>
      <origin rpy="0 3.14159265359 0" xyz="0 0 0"/>
    </visual>
  </link>
  <link name="end_link_3.0">
    <origin rpy="0 0 0" xyz="0 0 0"/>
  </link>
  <joint name="base_joint_3.0" type="fixed">
    <parent link="end_link_2.0"/>
    <child link="arduino_link_3.0"/>
  </joint>
  <joint name="battery_joint_3.0" type="fixed">
    <parent link="servo_link_3.0"/>
    <child link="battery_link_3.0"/>
    <origin rpy="0 0 0" xyz="0 -0.0005 0.025"/>
  </joint>
  <joint name="end_joint_3.0" type="fixed">
    <parent link="battery_link_3.0"/>
    <child link="end_link_3.0"/>
    <origin rpy="0 0 0" xyz="-0.0007 0.002 0.016"/>
  </joint>
  <joint name="module_joint_3.0" type="revolute">
    <parent link="arduino_link_3.0"/>
    <child link="servo_link_3.0"/>
    <origin rpy="0 0 0" xyz="0.0005 -0.0003 0.041"/>
    <axis xyz="0 1 0"/>
    <limit effort="1" lower="-1.57079632679" upper="1.57079632679" velocity="1"/>
  </joint>
  <xacro:property name="parent_link" value="2"/>
  <link name="arduino_link_4.0">
    <visual>
      <geometry>
        <mesh filename="package://pmr_description/meshes/moduleArduino.dae" scale="0.001 0.001 0.001"/>
      </geometry>
      <origin rpy="0 0 0" xyz="0 0 0.009"/>
    </visual>
  </link>
  <link name="servo_link_4.0">
    <visual>
      <geometry>
        <mesh filename="package://pmr_description/meshes/moduleServo.dae" scale="0.001 0.001 0.001"/>
      </geometry>
      <origin rpy="0 3.14159265359 0" xyz="0 0 0"/>
    </visual>
  </link>
  <link name="battery_link_4.0">
    <visual>
      <geometry>
        <mesh filename="package://pmr_description/meshes/moduleBattery.dae" scale="0.001 0.001 0.001"/>
      </geometry>
      <origin rpy="0 3.14159265359 0" xyz="0 0 0"/>
    </visual>
  </link>
  <link name="end_link_4.0">
    <origin rpy="0 0 0" xyz="0 0 0"/>
  </link>
  <joint name="base_joint_4.0" type="fixed">
    <parent link="end_link_3.0"/>
    <child link="arduino_link_4.0"/>
  </joint>
  <joint name="battery_joint_4.0" type="fixed">
    <parent link="servo_link_4.0"/>
    <child link="battery_link_4.0"/>
    <origin rpy="0 0 0" xyz="0 -0.0005 0.025"/>
  </joint>
  <joint name="end_joint_4.0" type="fixed">
    <parent link="battery_link_4.0"/>
    <child link="end_link_4.0"/>
    <origin rpy="0 0 0" xyz="-0.0007 0.002 0.016"/>
  </joint>
  <joint name="module_joint_4.0" type="revolute">
    <parent link="arduino_link_4.0"/>
    <child link="servo_link_4.0"/>
    <origin rpy="0 0 0" xyz="0.0005 -0.0003 0.041"/>
    <axis xyz="0 1 0"/>
    <limit effort="1" lower="-1.57079632679" upper="1.57079632679" velocity="1"/>
  </joint>
</robot>

