<?xml version="1.0" ?>
<!-- =================================================================================== -->
<!-- |    This document was autogenerated by xacro from tams/tams_ur5_setup/tams_ur5_setup_description/urdf/tams_ur5_setup.urdf.xacro | -->
<!-- |    EDITING THIS FILE BY HAND IS NOT RECOMMENDED                                 | -->
<!-- =================================================================================== -->
<robot name="tams_ur5_setup" xmlns:xacro="http://www.ros.org/wiki/xacro">
  <!-- tams corner -->
  <material name="white">
    <color rgba="1 1 1 1"/>
  </material>
  <material name="brown">
    <color rgba="0.87 0.72 0.53 1"/>
  </material>
  <material name="lightgray">
    <color rgba="0.6 0.6 0.6 1"/>
  </material>
  <link name="floor">
    <inertial>
      <origin xyz="2.5 2.5 0"/>
      <mass value="2000"/>
      <inertia ixx="1" ixy="0" ixz="0" iyy="1" iyz="0" izz="1"/>
    </inertial>
    <visual>
      <material name="black"/>
      <origin xyz="2.5 2.4175 0"/>
      <geometry>
        <box size="5.0 5.165 0.001"/>
      </geometry>
    </visual>
    <collision>
      <origin xyz="2.5 2.4175 0"/>
      <geometry>
        <box size="5.0 5.165 0.001"/>
      </geometry>
    </collision>
  </link>
  <gazebo reference="floor">
    <material>Gazebo/Blue</material>
    <turnGravityOff>false</turnGravityOff>
    <selfCollide>true</selfCollide>
    <!-- kp: stiffness kd: damping mu1, mu2: friction -->
    <mu1>100.0</mu1>
    <mu2>100.0</mu2>
    <kp>1000000.0</kp>
    <kd>1.0</kd>
  </gazebo>
  <link name="wall">
    <inertial>
      <origin xyz="-0.06 2.5 1.5"/>
      <mass value="2000"/>
      <inertia ixx="1" ixy="0" ixz="0" iyy="1" iyz="0" izz="1"/>
    </inertial>
    <visual>
      <material name="white"/>
      <origin xyz="-0.06 2.5 1.5"/>
      <geometry>
        <box size="0.12 5.0 3.0"/>
      </geometry>
    </visual>
    <collision>
      <origin xyz="-0.06 2.5 1.5"/>
      <geometry>
        <box size="0.12 5.0 3.0"/>
      </geometry>
    </collision>
  </link>
  <gazebo reference="wall">
    <material>Gazebo/Blue</material>
    <turnGravityOff>false</turnGravityOff>
    <selfCollide>true</selfCollide>
    <!-- kp: stiffness kd: damping mu1, mu2: friction -->
    <mu1>100.0</mu1>
    <mu2>100.0</mu2>
    <kp>1000000.0</kp>
    <kd>1.0</kd>
  </gazebo>
  <!-- tilted ur5 mount - the meshes are not centered at mount point so they are adjusted to fit to the frame -->
  <link name="ur5_mount">
    <visual>
      <material name="lightgray"/>
      <origin xyz="-0.0245 -0.09 -0.28"/>
      <geometry>
        <mesh filename="package://tams_ur5_setup_description/meshes/ur5_mount_binary_v3.dae" scale="0.001 0.001 0.001"/>
      </geometry>
    </visual>
    <collision>
      <origin xyz="-0.0245 -0.09 -0.28"/>
      <geometry>
        <mesh filename="package://tams_ur5_setup_description/meshes/ur5_mount_binary_v3.dae" scale="0.001 0.001 0.001"/>
      </geometry>
    </collision>
  </link>
  <link name="side_wall">
    <inertial>
      <origin xyz="0 0 0"/>
      <mass value="2000"/>
      <inertia ixx="1" ixy="0" ixz="0" iyy="1" iyz="0" izz="1"/>
    </inertial>
    <visual>
      <material name="white"/>
      <origin xyz="0 0 0"/>
      <geometry>
        <box size="5.0 0.12 3.0"/>
      </geometry>
    </visual>
    <collision>
      <origin xyz="0 0 0.0"/>
      <geometry>
        <box size="5.0 0.12 3.0"/>
      </geometry>
    </collision>
  </link>
  <gazebo reference="side_wall">
    <material>Gazebo/Blue</material>
    <turnGravityOff>false</turnGravityOff>
    <selfCollide>true</selfCollide>
    <!-- kp: stiffness kd: damping mu1, mu2: friction -->
    <mu1>100.0</mu1>
    <mu2>100.0</mu2>
    <kp>1000000.0</kp>
    <kd>1.0</kd>
  </gazebo>
  <link name="small_wall">
    <inertial>
      <origin xyz="0 0 0"/>
      <mass value="2000"/>
      <inertia ixx="1" ixy="0" ixz="0" iyy="1" iyz="0" izz="1"/>
    </inertial>
    <visual>
      <material name="white"/>
      <origin xyz="0 0 0"/>
      <geometry>
        <box size="0.19 0.165 3.0"/>
      </geometry>
    </visual>
    <collision>
      <origin xyz="0 0 0.0"/>
      <geometry>
        <!-- the collision model is 7cm wider due to security reasons -->
        <box size="0.33 0.305 3.0"/>
      </geometry>
    </collision>
  </link>
  <gazebo reference="small_wall">
    <material>Gazebo/Blue</material>
    <turnGravityOff>false</turnGravityOff>
    <selfCollide>true</selfCollide>
    <!-- kp: stiffness kd: damping mu1, mu2: friction -->
    <mu1>100.0</mu1>
    <mu2>100.0</mu2>
    <kp>1000000.0</kp>
    <kd>1.0</kd>
  </gazebo>
  <link name="cable_duct">
    <inertial>
      <origin xyz="0 0 0"/>
      <mass value="2000"/>
      <inertia ixx="1" ixy="0" ixz="0" iyy="1" iyz="0" izz="1"/>
    </inertial>
    <visual>
      <material name="lightgray"/>
      <origin xyz="0 0 0"/>
      <geometry>
        <box size="0.13 0.06 3.0"/>
      </geometry>
    </visual>
    <collision>
      <origin xyz="0 0 0"/>
      <geometry>
        <!-- the collision model is 7cm wider then the actual duct, because of an unmodelled ethernet port -->
        <box size="0.27 0.2 3.0"/>
      </geometry>
    </collision>
  </link>
  <gazebo reference="cable_duct">
    <material>Gazebo/Blue</material>
    <turnGravityOff>false</turnGravityOff>
    <selfCollide>true</selfCollide>
    <!-- kp: stiffness kd: damping mu1, mu2: friction -->
    <mu1>100.0</mu1>
    <mu2>100.0</mu2>
    <kp>1000000.0</kp>
    <kd>1.0</kd>
  </gazebo>
  <link name="table">
    <inertial>
      <origin xyz="0 0 0.375"/>
      <mass value="10"/>
      <inertia ixx="1" ixy="0" ixz="0" iyy="1" iyz="0" izz="1"/>
    </inertial>
    <visual>
      <material name="brown"/>
      <origin xyz="0 0 0.375"/>
      <geometry>
        <box size="0.80 1.0 0.75"/>
      </geometry>
    </visual>
    <!-- <collision>
      <origin xyz="0 0 ${tableheight/2}" />
      <geometry>
        <box size="0.80 1.0 ${tableheight}" />
      </geometry>
    </collision>  -->
    <collision>
      <origin xyz="-0.2 0 0.375"/>
      <geometry>
        <box size="1.2 1.0 0.75"/>
      </geometry>
    </collision>
  </link>
  <gazebo reference="table">
    <material>Gazebo/Blue</material>
    <turnGravityOff>false</turnGravityOff>
    <selfCollide>true</selfCollide>
    <!-- kp: stiffness kd: damping mu1, mu2: friction -->
    <mu1>100.0</mu1>
    <mu2>100.0</mu2>
    <kp>1000000.0</kp>
    <kd>1.0</kd>
  </gazebo>
  <link name="table_top"/>
  <link name="shelf">
    <inertial>
      <origin xyz="1.7 0 0"/>
      <mass value="60"/>
      <inertia ixx="1" ixy="0" ixz="0" iyy="1" iyz="0" izz="1"/>
    </inertial>
    <visual>
      <material name="lightgray"/>
      <origin xyz="0 1.7 0"/>
      <geometry>
        <box size="0.4 2 2.5"/>
      </geometry>
    </visual>
    <collision>
      <origin xyz="0 1.7 0"/>
      <geometry>
        <!-- the collision model is 7cm wider due to security reasons -->
        <box size="0.54 2.14 2.5"/>
      </geometry>
    </collision>
  </link>
  <gazebo reference="shelf">
    <material>Gazebo/Orange</material>
    <turnGravityOff>false</turnGravityOff>
    <selfCollide>true</selfCollide>
    <!-- kp: stiffness kd: damping mu1, mu2: friction -->
    <mu1>100.0</mu1>
    <mu2>100.0</mu2>
    <kp>1000000.0</kp>
    <kd>1.0</kd>
  </gazebo>
  <link name="april_tag_ur5">
    <inertial>
      <origin xyz="0 0 0"/>
      <mass value="2000"/>
      <inertia ixx="1" ixy="0" ixz="0" iyy="1" iyz="0" izz="1"/>
    </inertial>
    <visual>
      <material name="lightgray"/>
      <origin xyz="0 0 0"/>
      <geometry>
        <box size="0.166 0.166 0.01"/>
      </geometry>
    </visual>
    <collision>
      <origin xyz="0 0 0.0"/>
      <geometry>
        <box size="0.166 0.166 0.01"/>
      </geometry>
    </collision>
  </link>
  <gazebo reference="april_tag_ur5">
    <material>Gazebo/Blue</material>
    <turnGravityOff>false</turnGravityOff>
    <selfCollide>true</selfCollide>
    <mu1>100.0</mu1>
    <mu2>100.0</mu2>
    <kp>1000000.0</kp>
    <kd>1.0</kd>
  </gazebo>
  <link name="clock">
    <inertial>
      <origin xyz="0 0 0"/>
      <mass value="2000"/>
      <inertia ixx="1" ixy="0" ixz="0" iyy="1" iyz="0" izz="1"/>
    </inertial>
    <visual>
      <material name="lightgray"/>
      <origin xyz="0 0 0"/>
      <geometry>
        <cylinder length="0.06" radius="0.14"/>
      </geometry>
    </visual>
    <collision>
      <origin xyz="0 0 0.0"/>
      <geometry>
        <cylinder length="0.06" radius="0.14"/>
      </geometry>
    </collision>
  </link>
  <link name="turtlebot"/>
  <link name="turtlebot_holder"/>
  <joint name="floor_wall_joint" type="fixed">
    <parent link="floor"/>
    <child link="wall"/>
    <!-- The actual wall in the lab is slightly tilted, the rotation compensates approx 1 deg -->
    <origin rpy="0 0 0" xyz="0 0 0"/>
    <!--<origin xyz="0 0 0" rpy="0 0.06 0" />-->
  </joint>
  <joint name="wall_mount_joint" type="fixed">
    <parent link="wall"/>
    <child link="ur5_mount"/>
    <origin rpy="0 0 3.14159265" xyz="0.2255 0.7245 1.085"/>
  </joint>
  <joint name="side_wall_joint" type="fixed">
    <parent link="floor"/>
    <child link="side_wall"/>
    <!--<origin xyz="2.5 -0.06 1.5" rpy="0 0 0" />-->
    <origin rpy="0 0 0" xyz="2.5 -0.225 1.5"/>
  </joint>
  <joint name="small_wall_joint" type="fixed">
    <parent link="floor"/>
    <child link="small_wall"/>
    <!--<origin xyz="2.5 -0.06 1.5" rpy="0 0 0" />-->
    <origin rpy="0 0 0" xyz="0.07 -0.0825 1.5"/>
  </joint>
  <joint name="cable_duct_joint" type="fixed">
    <parent link="floor"/>
    <child link="cable_duct"/>
    <origin rpy="0 0 0" xyz="0.475 -0.135 1.5"/>
  </joint>
  <joint name="table_joint" type="fixed">
    <parent link="floor"/>
    <child link="table"/>
    <!-- actual wall is 2.5cm further back from table, but is modelled at the position of the small ur5 adapter plate -->
    <!-- <origin xyz="0.75 0.3 0" rpy="0 0 0" /> -->
    <origin rpy="0 0 0" xyz="0.89 0.74 0"/>
  </joint>
  <joint name="table_top_joint" type="fixed">
    <parent link="table"/>
    <child link="table_top"/>
    <origin rpy="0 0 0" xyz="0 0 0.75"/>
  </joint>
  <joint name="shelf_joint" type="fixed">
    <parent link="floor"/>
    <child link="shelf"/>
    <!-- actual shelf is a little smaller -->
    <origin rpy="0 0 0" xyz="0.2 1 1.25"/>
  </joint>
  <joint name="apriltag_ur5_joint" type="fixed">
    <parent link="wall"/>
    <child link="april_tag_ur5"/>
    <!--<origin xyz="-0.015 0.75 1.494" rpy="${-pi/2-0.05} 0.0 ${-pi/2}" />-->
    <!-- offset relative to the tilted wall -->
    <origin rpy="-1.570796325 0.0 -1.570796325" xyz="-0.01 0.75 1.494"/>
    <!-- offset relative to the tilted wall -->
  </joint>
  <joint name="clock_joint" type="fixed">
    <parent link="wall"/>
    <child link="clock"/>
    <origin rpy="-1.570796325 0.0 -1.570796325" xyz="0.03 0.82 1.993"/>
    <!-- offset relative to the tilted wall -->
  </joint>
  <joint name="turtlebot_joint" type="fixed">
    <parent link="world"/>
    <child link="turtlebot"/>
    <origin rpy="0.0 0.0 0.0" xyz="0.26 1.31 0.0"/>
  </joint>
  <joint name="turtlebot_holder_joint" type="fixed">
    <parent link="turtlebot"/>
    <child link="turtlebot_holder"/>
    <origin rpy="0.0 0.0 0.0" xyz="0.04 0.0 0.41"/>
  </joint>
  <!-- arm -->
  <!-- include macro definitions -->
  <!-- Inertia parameters -->
  <!-- This mass might be incorrect -->
  <!-- Kinematic model -->
  <!-- Properties from urcontrol.conf -->
  <!--
    DH for UR5:
    a = [0.00000, -0.42500, -0.39225,  0.00000,  0.00000,  0.0000]
    d = [0.089159,  0.00000,  0.00000,  0.10915,  0.09465,  0.0823]
    alpha = [ 1.570796327, 0, 0, 1.570796327, -1.570796327, 0 ]
    q_home_offset = [0, -1.570796327, 0, -1.570796327, 0, 0]
    joint_direction = [-1, -1, 1, 1, 1, 1]
    mass = [3.7000, 8.3930, 2.2750, 1.2190, 1.2190, 0.1879]
    center_of_mass = [ [0, -0.02561, 0.00193], [0.2125, 0, 0.11336], [0.11993, 0.0, 0.0265], [0, -0.0018, 0.01634], [0, 0.0018,0.01634], [0, 0, -0.001159] ]
  -->
  <!-- Arbitrary offsets for shoulder/elbow joints -->
  <!-- measured from model -->
  <!-- measured from model -->
  <!-- link lengths used in model -->
  <!--property name="shoulder_height" value="0.089159" /-->
  <!--property name="shoulder_offset" value="0.13585" /-->
  <!-- shoulder_offset - elbow_offset + wrist_1_length = 0.10915 -->
  <!--property name="upper_arm_length" value="0.42500" /-->
  <!--property name="elbow_offset" value="0.1197" /-->
  <!-- CAD measured -->
  <!--property name="forearm_length" value="0.39225" /-->
  <!--property name="wrist_1_length" value="0.093" /-->
  <!-- CAD measured -->
  <!--property name="wrist_2_length" value="0.09465" /-->
  <!-- In CAD this distance is 0.930, but in the spec it is 0.09465 -->
  <!--property name="wrist_3_length" value="0.0823" /-->
  <!-- manually measured -->
  <!-- manually measured -->
  <!-- manually measured -->
  <!-- manually measured -->
  <!-- manually measured -->
  <!-- 
    The parameter xamla_cap enables optional support for Xamla's rounded cap (wrist 2), 
    increasing the collision free space. 
    If set, visual and collision meshes are loaded from the files provided in the following
    repository: https://github.com/Xamla/xamla_egomo.
    More information on the cap and the 3D-printable models can be found at:
    https://github.com/Xamla/xamla_egomo/tree/master/egomo_3d_printed_parts/egomo-1  
  -->
  <!-- arm -->
  <link name="ur5_base_link">
    <visual>
      <geometry>
        <mesh filename="package://ur_description/meshes/ur5/visual/base.dae"/>
      </geometry>
      <material name="LightGrey">
        <color rgba="0.7 0.7 0.7 1.0"/>
      </material>
    </visual>
    <collision>
      <geometry>
        <mesh filename="package://ur_description/meshes/ur5/collision/base.stl"/>
      </geometry>
    </collision>
    <inertial>
      <mass value="4.0"/>
      <origin rpy="0 0 0" xyz="0.0 0.0 0.0"/>
      <inertia ixx="0.00443333156" ixy="0.0" ixz="0.0" iyy="0.00443333156" iyz="0.0" izz="0.0072"/>
    </inertial>
  </link>
  <joint name="ur5_shoulder_pan_joint" type="revolute">
    <parent link="ur5_base_link"/>
    <child link="ur5_shoulder_link"/>
    <origin rpy="0.0 0.0 0.0" xyz="0.0 0.0 0.089159"/>
    <axis xyz="0 0 1"/>
    <limit effort="150.0" lower="-3.14159265" upper="3.14159265" velocity="3.15"/>
    <dynamics damping="0.0" friction="0.0"/>
  </joint>
  <link name="ur5_shoulder_link">
    <visual>
      <geometry>
        <mesh filename="package://ur_description/meshes/ur5/visual/shoulder.dae"/>
      </geometry>
      <material name="LightGrey">
        <color rgba="0.7 0.7 0.7 1.0"/>
      </material>
    </visual>
    <collision>
      <geometry>
        <mesh filename="package://ur_description/meshes/ur5/collision/shoulder.stl"/>
      </geometry>
    </collision>
    <inertial>
      <mass value="3.7"/>
      <origin rpy="0 0 0" xyz="0.0 0.0 0.0"/>
      <inertia ixx="0.010267495893" ixy="0.0" ixz="0.0" iyy="0.010267495893" iyz="0.0" izz="0.00666"/>
    </inertial>
  </link>
  <joint name="ur5_shoulder_lift_joint" type="revolute">
    <parent link="ur5_shoulder_link"/>
    <child link="ur5_upper_arm_link"/>
    <origin rpy="0.0 1.570796325 0.0" xyz="0.0 0.13585 0.0"/>
    <axis xyz="0 1 0"/>
    <limit effort="150.0" lower="-3.9269908125" upper="0.7853981625" velocity="3.15"/>
    <dynamics damping="0.0" friction="0.0"/>
  </joint>
  <link name="ur5_upper_arm_link">
    <visual>
      <geometry>
        <mesh filename="package://ur_description/meshes/ur5/visual/upperarm.dae"/>
      </geometry>
      <material name="LightGrey">
        <color rgba="0.7 0.7 0.7 1.0"/>
      </material>
    </visual>
    <collision>
      <geometry>
        <mesh filename="package://ur_description/meshes/ur5/collision/upperarm.stl"/>
      </geometry>
    </collision>
    <inertial>
      <mass value="8.393"/>
      <origin rpy="0 0 0" xyz="0.0 0.0 0.28"/>
      <inertia ixx="0.22689067591" ixy="0.0" ixz="0.0" iyy="0.22689067591" iyz="0.0" izz="0.0151074"/>
    </inertial>
  </link>
  <joint name="ur5_elbow_joint" type="revolute">
    <parent link="ur5_upper_arm_link"/>
    <child link="ur5_forearm_link"/>
    <origin rpy="0.0 0.0 0.0" xyz="0.0 -0.1197 0.425"/>
    <axis xyz="0 1 0"/>
    <limit effort="150.0" lower="-3.14159265" upper="0.0" velocity="3.15"/>
    <dynamics damping="0.0" friction="0.0"/>
  </joint>
  <link name="ur5_forearm_link">
    <visual>
      <geometry>
        <mesh filename="package://ur_description/meshes/ur5/visual/forearm.dae"/>
      </geometry>
      <material name="LightGrey">
        <color rgba="0.7 0.7 0.7 1.0"/>
      </material>
    </visual>
    <collision>
      <geometry>
        <mesh filename="package://ur_description/meshes/ur5/collision/forearm.stl"/>
      </geometry>
    </collision>
    <inertial>
      <mass value="2.275"/>
      <origin rpy="0 0 0" xyz="0.0 0.0 0.25"/>
      <inertia ixx="0.049443313556" ixy="0.0" ixz="0.0" iyy="0.049443313556" iyz="0.0" izz="0.004095"/>
    </inertial>
  </link>
  <joint name="ur5_wrist_1_joint" type="revolute">
    <parent link="ur5_forearm_link"/>
    <child link="ur5_wrist_1_link"/>
    <origin rpy="0.0 1.570796325 0.0" xyz="0.0 0.0 0.39225"/>
    <axis xyz="0 1 0"/>
    <limit effort="28.0" lower="-3.14159265" upper="3.14159265" velocity="3.2"/>
    <dynamics damping="0.0" friction="0.0"/>
  </joint>
  <link name="ur5_wrist_1_link">
    <visual>
      <geometry>
        <mesh filename="package://ur_description/meshes/ur5/visual/wrist1.dae"/>
      </geometry>
      <material name="LightGrey">
        <color rgba="0.7 0.7 0.7 1.0"/>
      </material>
    </visual>
    <collision>
      <geometry>
        <mesh filename="package://ur_description/meshes/ur5/collision/wrist1.stl"/>
      </geometry>
    </collision>
    <inertial>
      <mass value="1.219"/>
      <origin rpy="0 0 0" xyz="0.0 0.0 0.0"/>
      <inertia ixx="0.111172755531" ixy="0.0" ixz="0.0" iyy="0.111172755531" iyz="0.0" izz="0.21942"/>
    </inertial>
  </link>
  <joint name="ur5_wrist_2_joint" type="revolute">
    <parent link="ur5_wrist_1_link"/>
    <child link="ur5_wrist_2_link"/>
    <origin rpy="0.0 0.0 0.0" xyz="0.0 0.093 0.0"/>
    <axis xyz="0 0 1"/>
    <!-- <xacro:unless value="${joint_limited}">
        <limit lower="${-2.0 * pi}" upper="${2.0 * pi}" effort="28.0" velocity="3.2"/>
      </xacro:unless>
      <xacro:if value="${joint_limited}">
        <limit lower="${-pi}" upper="${pi}" effort="28.0" velocity="3.2"/>
      </xacro:if>-->
    <limit effort="28.0" lower="-6.2831853" upper="6.2831853" velocity="3.2"/>
    <dynamics damping="0.0" friction="0.0"/>
  </joint>
  <link name="ur5_wrist_2_link">
    <visual>
      <geometry>
        <mesh filename="package://ur_description/meshes/ur5/visual/wrist2_rounded.dae"/>
      </geometry>
      <material name="LightGrey">
        <color rgba="0.7 0.7 0.7 1.0"/>
      </material>
    </visual>
    <collision>
      <geometry>
        <mesh filename="package://ur_description/meshes/ur5/collision/wrist2_rounded.stl"/>
      </geometry>
    </collision>
    <inertial>
      <mass value="1.219"/>
      <origin rpy="0 0 0" xyz="0.0 0.0 0.0"/>
      <inertia ixx="0.111172755531" ixy="0.0" ixz="0.0" iyy="0.111172755531" iyz="0.0" izz="0.21942"/>
    </inertial>
  </link>
  <joint name="ur5_wrist_3_joint" type="revolute">
    <parent link="ur5_wrist_2_link"/>
    <child link="ur5_wrist_3_link"/>
    <origin rpy="0.0 0.0 0.0" xyz="0.0 0.0 0.09465"/>
    <axis xyz="0 1 0"/>
    <!-- <xacro:unless value="${joint_limited}">
        <limit lower="${-2.0 * pi}" upper="${2.0 * pi}" effort="28.0" velocity="3.2"/>
      </xacro:unless>
      <xacro:if value="${joint_limited}">
        <limit lower="${-pi}" upper="${pi}" effort="28.0" velocity="3.2"/>
      </xacro:if>-->
    <limit effort="28.0" lower="-6.2831853" upper="6.2831853" velocity="3.2"/>
    <dynamics damping="0.0" friction="0.0"/>
  </joint>
  <link name="ur5_wrist_3_link">
    <visual>
      <geometry>
        <mesh filename="package://ur_description/meshes/ur5/visual/wrist3.dae"/>
      </geometry>
      <material name="LightGrey">
        <color rgba="0.7 0.7 0.7 1.0"/>
      </material>
    </visual>
    <collision>
      <geometry>
        <mesh filename="package://ur_description/meshes/ur5/collision/wrist3.stl"/>
      </geometry>
    </collision>
    <inertial>
      <mass value="0.1879"/>
      <origin rpy="0 0 0" xyz="0.0 0.0 0.0"/>
      <inertia ixx="0.0171364731454" ixy="0.0" ixz="0.0" iyy="0.0171364731454" iyz="0.0" izz="0.033822"/>
    </inertial>
  </link>
  <joint name="ur5_ee_fixed_joint" type="fixed">
    <parent link="ur5_wrist_3_link"/>
    <child link="ur5_ee_link"/>
    <origin rpy="0.0 0.0 1.570796325" xyz="0.0 0.0823 0.0"/>
  </joint>
  <link name="ur5_ee_link">
    <collision>
      <geometry>
        <box size="0.01 0.01 0.01"/>
      </geometry>
      <origin rpy="0 0 0" xyz="-0.01 0 0"/>
    </collision>
  </link>
  <transmission name="ur5_shoulder_pan_trans">
    <type>transmission_interface/SimpleTransmission</type>
    <joint name="ur5_shoulder_pan_joint">
      <hardwareInterface>PositionJointInterface</hardwareInterface>
    </joint>
    <actuator name="ur5_shoulder_pan_motor">
      <mechanicalReduction>1</mechanicalReduction>
    </actuator>
  </transmission>
  <transmission name="ur5_shoulder_lift_trans">
    <type>transmission_interface/SimpleTransmission</type>
    <joint name="ur5_shoulder_lift_joint">
      <hardwareInterface>PositionJointInterface</hardwareInterface>
    </joint>
    <actuator name="ur5_shoulder_lift_motor">
      <mechanicalReduction>1</mechanicalReduction>
    </actuator>
  </transmission>
  <transmission name="ur5_elbow_trans">
    <type>transmission_interface/SimpleTransmission</type>
    <joint name="ur5_elbow_joint">
      <hardwareInterface>PositionJointInterface</hardwareInterface>
    </joint>
    <actuator name="ur5_elbow_motor">
      <mechanicalReduction>1</mechanicalReduction>
    </actuator>
  </transmission>
  <transmission name="ur5_wrist_1_trans">
    <type>transmission_interface/SimpleTransmission</type>
    <joint name="ur5_wrist_1_joint">
      <hardwareInterface>PositionJointInterface</hardwareInterface>
    </joint>
    <actuator name="ur5_wrist_1_motor">
      <mechanicalReduction>1</mechanicalReduction>
    </actuator>
  </transmission>
  <transmission name="ur5_wrist_2_trans">
    <type>transmission_interface/SimpleTransmission</type>
    <joint name="ur5_wrist_2_joint">
      <hardwareInterface>PositionJointInterface</hardwareInterface>
    </joint>
    <actuator name="ur5_wrist_2_motor">
      <mechanicalReduction>1</mechanicalReduction>
    </actuator>
  </transmission>
  <transmission name="ur5_wrist_3_trans">
    <type>transmission_interface/SimpleTransmission</type>
    <joint name="ur5_wrist_3_joint">
      <hardwareInterface>PositionJointInterface</hardwareInterface>
    </joint>
    <actuator name="ur5_wrist_3_motor">
      <mechanicalReduction>1</mechanicalReduction>
    </actuator>
  </transmission>
  <!-- nothing to do here at the moment -->
  <!-- ROS base_link to UR 'Base' Coordinates transform -->
  <link name="ur5_base"/>
  <joint name="ur5_base_link-base_fixed_joint" type="fixed">
    <!-- NOTE: this rotation is only needed as long as base_link itself is
                 not corrected wrt the real robot (ie: rotated over 180
                 degrees)
      -->
    <origin rpy="0 0 -3.14159265" xyz="0 0 0"/>
    <parent link="ur5_base_link"/>
    <child link="ur5_base"/>
  </joint>
  <!-- Frame coincident with all-zeros TCP on UR controller -->
  <link name="ur5_tool0"/>
  <joint name="ur5_wrist_3_link-tool0_fixed_joint" type="fixed">
    <origin rpy="-1.570796325 0 0" xyz="0 0.0823 0"/>
    <parent link="ur5_wrist_3_link"/>
    <child link="ur5_tool0"/>
  </joint>
  <!-- ft_adapter -->
  <link name="ft_adapter">
    <!-- TODO values for inertial are not correct -->
    <inertial>
      <mass value="0.2"/>
      <origin xyz="0.0 0.0 0.0"/>
      <inertia ixx="0.002708332" ixy="0.0" ixz="0.0" iyy="0.000708333" iyz="0.0" izz="0.003333332"/>
    </inertial>
    <visual>
      <origin rpy="0 0 0.0" xyz="0.0 0 0.0"/>
      <geometry>
        <box size="0.088 0.088 0.009"/>
      </geometry>
      <material name="gray">
        <color rgba="0.2 0.2 0.2 1"/>
      </material>
    </visual>
    <collision>
      <origin rpy="0 0 0.0" xyz="0.0 0 0.0"/>
      <geometry>
        <box size="0.088 0.088 0.009"/>
      </geometry>
    </collision>
  </link>
  <joint name="ft_adapter_joint" type="fixed">
    <origin rpy="0.0 1.570796325 0.0" xyz="0.0045 0.0 0.0"/>
    <child link="ft_adapter"/>
    <parent link="ur5_ee_link"/>
  </joint>
  <!-- ft150 -->
  <!-- mount the fts to the robot -->
  <joint name="ft_fts_fix" type="fixed">
    <!--In most cases origin would be flange adapter plate: <origin xyz="0 0 0.009" rpy="0 0 0"/> /-->
    <origin rpy="0.0 -1.570796325 3.14159265" xyz="0.009 0.0 0.0"/>
    <parent link="ur5_ee_link"/>
    <child link="ft_fts_robotside"/>
  </joint>
  <link name="ft_fts_robotside">
    <inertial>
      <origin rpy="0 0 0" xyz="0 0 0.01875"/>
      <mass value="0.65"/>
      <inertia ixx="0.000661171875" ixy="0" ixz="0" iyy="0.000661171875" iyz="0" izz="0.00117"/>
    </inertial>
    <visual>
      <origin rpy="0 0 0" xyz="0 0 0"/>
      <geometry>
        <mesh filename="package://robotiq_force_torque_sensor/meshes/visual/robotiq_fts150.dae"/>
      </geometry>
      <material name="black"/>
    </visual>
    <collision>
      <origin rpy="0 0 0" xyz="0 0 0"/>
      <geometry>
        <mesh filename="package://robotiq_force_torque_sensor/meshes/collision/robotiq_fts150.dae"/>
      </geometry>
    </collision>
  </link>
  <!-- virtual measurement frame -->
  <joint name="ft_measurment_joint" type="fixed">
    <origin rpy="0 0 0" xyz="0 0 0.01625"/>
    <parent link="ft_fts_robotside"/>
    <child link="ft_robotiq_force_torque_frame_id"/>
  </joint>
  <link name="ft_robotiq_force_torque_frame_id"/>
  <!-- toolside frame -->
  <joint name="ft_toolside_joint" type="fixed">
    <origin rpy="0 0 0" xyz="0 0 0.0375"/>
    <parent link="ft_fts_robotside"/>
    <child link="ft_fts_toolside"/>
  </joint>
  <link name="ft_fts_toolside"/>
  <!-- tool0 frame -->
  <link name="tool0"/>
  <joint name="ft_fts_toolside_tool0" type="fixed">
    <parent link="ft_fts_toolside"/>
    <child link="tool0"/>
    <origin rpy="0.0 -1.570796325 0.0" xyz="0.0 0.0 0.0"/>
  </joint>
  <!-- s_model_adapter -->
  <link name="s_model_adapter">
    <!-- TODO values for inertial are not correct -->
    <inertial>
      <mass value="0.2"/>
      <origin xyz="0.0 0.0 0.0"/>
      <inertia ixx="0.002708332" ixy="0.0" ixz="0.0" iyy="0.000708333" iyz="0.0" izz="0.003333332"/>
    </inertial>
    <visual>
      <origin rpy="0 0 0.0" xyz="0.0 0 0.0"/>
      <geometry>
        <cylinder length="0.035" radius="0.06"/>
      </geometry>
      <material name="gray">
        <color rgba="0.2 0.2 0.2 1"/>
      </material>
    </visual>
    <visual>
      <origin rpy="0 0 0.0" xyz="0.0725 0 0"/>
      <geometry>
        <box size="0.035 0.035 0.035"/>
      </geometry>
      <material name="gray">
        <color rgba="0.2 0.2 0.2 1"/>
      </material>
    </visual>
    <collision>
      <origin rpy="0 0 0.0" xyz="0.0 0 0.0"/>
      <geometry>
        <cylinder length="0.035" radius="0.06"/>
      </geometry>
    </collision>
    <collision>
      <origin rpy="0 0 0.0" xyz="0.0725 0 0"/>
      <geometry>
        <box size="0.035 0.035 0.035"/>
      </geometry>
    </collision>
  </link>
  <joint name="s_model_adapter_joint" type="fixed">
    <origin rpy="0.0 0.0 0.0" xyz="0.0 0.0 0.015"/>
    <child link="s_model_adapter"/>
    <parent link="ft_fts_toolside"/>
  </joint>
  <!-- the adaptive gripper -->
  <!-- link list -->
  <link name="s_model_finger_1_link_0">
    <visual>
      <origin rpy="0 0 0" xyz="0.020 0 0"/>
      <geometry>
        <mesh filename="package://robotiq_s_model_visualization/meshes/s-model_articulated/visual/link_0.dae"/>
      </geometry>
      <material name="gray">
        <color rgba="0.2 0.2 0.2 1"/>
      </material>
    </visual>
    <collision>
      <origin rpy="0 0 0" xyz="0.020 0 0"/>
      <geometry>
        <mesh filename="package://robotiq_s_model_visualization/meshes/s-model_articulated/collision/link_0.dae"/>
      </geometry>
      <material name="yellow">
        <color rgba="0 1 1 1"/>
      </material>
    </collision>
    <inertial>
      <origin rpy="0 0 0" xyz="0 0 0"/>
      <mass value="0.05"/>
      <inertia ixx="0.01" ixy="-0.00002" ixz="0.00001" iyy="0.0008" iyz="0" izz="0.001"/>
    </inertial>
  </link>
  <link name="s_model_finger_1_link_1">
    <visual>
      <origin rpy="0 0 -0.52" xyz="0.050 -.028 0"/>
      <geometry>
        <mesh filename="package://robotiq_s_model_visualization/meshes/s-model_articulated/visual/link_1.dae"/>
      </geometry>
      <material name="gray"/>
    </visual>
    <collision>
      <origin rpy="0 0 -0.52" xyz="0.050 -.028 0"/>
      <geometry>
        <mesh filename="package://robotiq_s_model_visualization/meshes/s-model_articulated/collision/link_1.dae"/>
      </geometry>
      <material name="yellow"/>
    </collision>
    <inertial>
      <origin rpy="0 0 0" xyz="0 0 0"/>
      <mass value="0.15"/>
      <inertia ixx="0.001859" ixy="-0.000376" ixz="0.000028" iyy="0.012756" iyz="0" izz="0.0024"/>
    </inertial>
  </link>
  <link name="s_model_finger_1_link_2">
    <!--
			NOTE: This link has an offset in the z-direction based on the models that were
			used to generate grap-it poses.  With the offset below the model appears visually
			correct, but it is suspect.
			-->
    <visual>
      <origin rpy="0 0 0" xyz="0.039 0 0.0075"/>
      <geometry>
        <mesh filename="package://robotiq_s_model_visualization/meshes/s-model_articulated/visual/link_2.dae"/>
      </geometry>
      <material name="gray"/>
    </visual>
    <collision>
      <origin rpy="0 0 0" xyz="0.039 0 0.0075"/>
      <geometry>
        <mesh filename="package://robotiq_s_model_visualization/meshes/s-model_articulated/collision/link_2.dae"/>
      </geometry>
      <material name="yellow"/>
    </collision>
    <inertial>
      <origin rpy="0 0 0" xyz="0 0 0"/>
      <mass value="0.15"/>
      <inertia ixx="0.001859" ixy="-0.000376" ixz="0.000028" iyy="0.012756" iyz="0" izz="0.0024"/>
    </inertial>
  </link>
  <link name="s_model_finger_1_link_3">
    <visual>
      <origin rpy="0 0 0.52" xyz="0 0 0"/>
      <geometry>
        <mesh filename="package://robotiq_s_model_visualization/meshes/s-model_articulated/visual/link_3.dae"/>
      </geometry>
      <material name="gray"/>
    </visual>
    <collision>
      <origin rpy="0 0 0.52" xyz="0 0 0"/>
      <geometry>
        <mesh filename="package://robotiq_s_model_visualization/meshes/s-model_articulated/collision/link_3.dae"/>
      </geometry>
      <material name="yellow"/>
    </collision>
    <inertial>
      <origin rpy="0 0 0" xyz="0 0 0"/>
      <mass value="0.05"/>
      <inertia ixx="0.001239" ixy="-0.000251" ixz="0.000019" iyy="0.00085" iyz="0" izz="0.001632"/>
    </inertial>
  </link>
  <!-- end of link list -->
  <!-- joint list -->
  <joint name="s_model_finger_1_joint_1" type="revolute">
    <parent link="s_model_finger_1_link_0"/>
    <child link="s_model_finger_1_link_1"/>
    <axis xyz="0 0 1"/>
    <origin rpy="0 0 0" xyz="0.020 0 0"/>
    <limit effort="100" lower="0.0495" upper="1.2218" velocity="100"/>
  </joint>
  <joint name="s_model_finger_1_joint_2" type="revolute">
    <parent link="s_model_finger_1_link_1"/>
    <child link="s_model_finger_1_link_2"/>
    <axis xyz="0 0 1"/>
    <origin rpy="0 0 -0.52" xyz="0.050 -.028 0"/>
    <limit effort="100" lower="0.0" upper="1.5708" velocity="100"/>
  </joint>
  <joint name="s_model_finger_1_joint_3" type="revolute">
    <parent link="s_model_finger_1_link_2"/>
    <child link="s_model_finger_1_link_3"/>
    <axis xyz="0 0 1"/>
    <origin rpy="0 0 0" xyz="0.039 0 0"/>
    <limit effort="100" lower="-1.2217" upper="-0.0523" velocity="100"/>
  </joint>
  <!-- end of joint list -->
  <!-- link list -->
  <link name="s_model_finger_2_link_0">
    <visual>
      <origin rpy="0 0 0" xyz="0.020 0 0"/>
      <geometry>
        <mesh filename="package://robotiq_s_model_visualization/meshes/s-model_articulated/visual/link_0.dae"/>
      </geometry>
      <material name="gray">
        <color rgba="0.2 0.2 0.2 1"/>
      </material>
    </visual>
    <collision>
      <origin rpy="0 0 0" xyz="0.020 0 0"/>
      <geometry>
        <mesh filename="package://robotiq_s_model_visualization/meshes/s-model_articulated/collision/link_0.dae"/>
      </geometry>
      <material name="yellow">
        <color rgba="0 1 1 1"/>
      </material>
    </collision>
    <inertial>
      <origin rpy="0 0 0" xyz="0 0 0"/>
      <mass value="0.05"/>
      <inertia ixx="0.01" ixy="-0.00002" ixz="0.00001" iyy="0.0008" iyz="0" izz="0.001"/>
    </inertial>
  </link>
  <link name="s_model_finger_2_link_1">
    <visual>
      <origin rpy="0 0 -0.52" xyz="0.050 -.028 0"/>
      <geometry>
        <mesh filename="package://robotiq_s_model_visualization/meshes/s-model_articulated/visual/link_1.dae"/>
      </geometry>
      <material name="gray"/>
    </visual>
    <collision>
      <origin rpy="0 0 -0.52" xyz="0.050 -.028 0"/>
      <geometry>
        <mesh filename="package://robotiq_s_model_visualization/meshes/s-model_articulated/collision/link_1.dae"/>
      </geometry>
      <material name="yellow"/>
    </collision>
    <inertial>
      <origin rpy="0 0 0" xyz="0 0 0"/>
      <mass value="0.15"/>
      <inertia ixx="0.001859" ixy="-0.000376" ixz="0.000028" iyy="0.012756" iyz="0" izz="0.0024"/>
    </inertial>
  </link>
  <link name="s_model_finger_2_link_2">
    <!--
			NOTE: This link has an offset in the z-direction based on the models that were
			used to generate grap-it poses.  With the offset below the model appears visually
			correct, but it is suspect.
			-->
    <visual>
      <origin rpy="0 0 0" xyz="0.039 0 0.0075"/>
      <geometry>
        <mesh filename="package://robotiq_s_model_visualization/meshes/s-model_articulated/visual/link_2.dae"/>
      </geometry>
      <material name="gray"/>
    </visual>
    <collision>
      <origin rpy="0 0 0" xyz="0.039 0 0.0075"/>
      <geometry>
        <mesh filename="package://robotiq_s_model_visualization/meshes/s-model_articulated/collision/link_2.dae"/>
      </geometry>
      <material name="yellow"/>
    </collision>
    <inertial>
      <origin rpy="0 0 0" xyz="0 0 0"/>
      <mass value="0.15"/>
      <inertia ixx="0.001859" ixy="-0.000376" ixz="0.000028" iyy="0.012756" iyz="0" izz="0.0024"/>
    </inertial>
  </link>
  <link name="s_model_finger_2_link_3">
    <visual>
      <origin rpy="0 0 0.52" xyz="0 0 0"/>
      <geometry>
        <mesh filename="package://robotiq_s_model_visualization/meshes/s-model_articulated/visual/link_3.dae"/>
      </geometry>
      <material name="gray"/>
    </visual>
    <collision>
      <origin rpy="0 0 0.52" xyz="0 0 0"/>
      <geometry>
        <mesh filename="package://robotiq_s_model_visualization/meshes/s-model_articulated/collision/link_3.dae"/>
      </geometry>
      <material name="yellow"/>
    </collision>
    <inertial>
      <origin rpy="0 0 0" xyz="0 0 0"/>
      <mass value="0.05"/>
      <inertia ixx="0.001239" ixy="-0.000251" ixz="0.000019" iyy="0.00085" iyz="0" izz="0.001632"/>
    </inertial>
  </link>
  <!-- end of link list -->
  <!-- joint list -->
  <joint name="s_model_finger_2_joint_1" type="revolute">
    <parent link="s_model_finger_2_link_0"/>
    <child link="s_model_finger_2_link_1"/>
    <axis xyz="0 0 1"/>
    <origin rpy="0 0 0" xyz="0.020 0 0"/>
    <limit effort="100" lower="0.0495" upper="1.2218" velocity="100"/>
  </joint>
  <joint name="s_model_finger_2_joint_2" type="revolute">
    <parent link="s_model_finger_2_link_1"/>
    <child link="s_model_finger_2_link_2"/>
    <axis xyz="0 0 1"/>
    <origin rpy="0 0 -0.52" xyz="0.050 -.028 0"/>
    <limit effort="100" lower="0.0" upper="1.5708" velocity="100"/>
  </joint>
  <joint name="s_model_finger_2_joint_3" type="revolute">
    <parent link="s_model_finger_2_link_2"/>
    <child link="s_model_finger_2_link_3"/>
    <axis xyz="0 0 1"/>
    <origin rpy="0 0 0" xyz="0.039 0 0"/>
    <limit effort="100" lower="-1.2217" upper="-0.0523" velocity="100"/>
  </joint>
  <!-- end of joint list -->
  <!-- link list -->
  <link name="s_model_finger_middle_link_0">
    <visual>
      <origin rpy="0 0 0" xyz="0.020 0 0"/>
      <geometry>
        <mesh filename="package://robotiq_s_model_visualization/meshes/s-model_articulated/visual/link_0.dae"/>
      </geometry>
      <material name="gray">
        <color rgba="0.2 0.2 0.2 1"/>
      </material>
    </visual>
    <collision>
      <origin rpy="0 0 0" xyz="0.020 0 0"/>
      <geometry>
        <mesh filename="package://robotiq_s_model_visualization/meshes/s-model_articulated/collision/link_0.dae"/>
      </geometry>
      <material name="yellow">
        <color rgba="0 1 1 1"/>
      </material>
    </collision>
    <inertial>
      <origin rpy="0 0 0" xyz="0 0 0"/>
      <mass value="0.05"/>
      <inertia ixx="0.01" ixy="-0.00002" ixz="0.00001" iyy="0.0008" iyz="0" izz="0.001"/>
    </inertial>
  </link>
  <link name="s_model_finger_middle_link_1">
    <visual>
      <origin rpy="0 0 -0.52" xyz="0.050 -.028 0"/>
      <geometry>
        <mesh filename="package://robotiq_s_model_visualization/meshes/s-model_articulated/visual/link_1.dae"/>
      </geometry>
      <material name="gray"/>
    </visual>
    <collision>
      <origin rpy="0 0 -0.52" xyz="0.050 -.028 0"/>
      <geometry>
        <mesh filename="package://robotiq_s_model_visualization/meshes/s-model_articulated/collision/link_1.dae"/>
      </geometry>
      <material name="yellow"/>
    </collision>
    <inertial>
      <origin rpy="0 0 0" xyz="0 0 0"/>
      <mass value="0.15"/>
      <inertia ixx="0.001859" ixy="-0.000376" ixz="0.000028" iyy="0.012756" iyz="0" izz="0.0024"/>
    </inertial>
  </link>
  <link name="s_model_finger_middle_link_2">
    <!--
			NOTE: This link has an offset in the z-direction based on the models that were
			used to generate grap-it poses.  With the offset below the model appears visually
			correct, but it is suspect.
			-->
    <visual>
      <origin rpy="0 0 0" xyz="0.039 0 0.0075"/>
      <geometry>
        <mesh filename="package://robotiq_s_model_visualization/meshes/s-model_articulated/visual/link_2.dae"/>
      </geometry>
      <material name="gray"/>
    </visual>
    <collision>
      <origin rpy="0 0 0" xyz="0.039 0 0.0075"/>
      <geometry>
        <mesh filename="package://robotiq_s_model_visualization/meshes/s-model_articulated/collision/link_2.dae"/>
      </geometry>
      <material name="yellow"/>
    </collision>
    <inertial>
      <origin rpy="0 0 0" xyz="0 0 0"/>
      <mass value="0.15"/>
      <inertia ixx="0.001859" ixy="-0.000376" ixz="0.000028" iyy="0.012756" iyz="0" izz="0.0024"/>
    </inertial>
  </link>
  <link name="s_model_finger_middle_link_3">
    <visual>
      <origin rpy="0 0 0.52" xyz="0 0 0"/>
      <geometry>
        <mesh filename="package://robotiq_s_model_visualization/meshes/s-model_articulated/visual/link_3.dae"/>
      </geometry>
      <material name="gray"/>
    </visual>
    <collision>
      <origin rpy="0 0 0.52" xyz="0 0 0"/>
      <geometry>
        <mesh filename="package://robotiq_s_model_visualization/meshes/s-model_articulated/collision/link_3.dae"/>
      </geometry>
      <material name="yellow"/>
    </collision>
    <inertial>
      <origin rpy="0 0 0" xyz="0 0 0"/>
      <mass value="0.05"/>
      <inertia ixx="0.001239" ixy="-0.000251" ixz="0.000019" iyy="0.00085" iyz="0" izz="0.001632"/>
    </inertial>
  </link>
  <!-- end of link list -->
  <!-- joint list -->
  <joint name="s_model_finger_middle_joint_1" type="revolute">
    <parent link="s_model_finger_middle_link_0"/>
    <child link="s_model_finger_middle_link_1"/>
    <axis xyz="0 0 1"/>
    <origin rpy="0 0 0" xyz="0.020 0 0"/>
    <limit effort="100" lower="0.0495" upper="1.2218" velocity="100"/>
  </joint>
  <joint name="s_model_finger_middle_joint_2" type="revolute">
    <parent link="s_model_finger_middle_link_1"/>
    <child link="s_model_finger_middle_link_2"/>
    <axis xyz="0 0 1"/>
    <origin rpy="0 0 -0.52" xyz="0.050 -.028 0"/>
    <limit effort="100" lower="0.0" upper="1.5708" velocity="100"/>
  </joint>
  <joint name="s_model_finger_middle_joint_3" type="revolute">
    <parent link="s_model_finger_middle_link_2"/>
    <child link="s_model_finger_middle_link_3"/>
    <axis xyz="0 0 1"/>
    <origin rpy="0 0 0" xyz="0.039 0 0"/>
    <limit effort="100" lower="-1.2217" upper="-0.0523" velocity="100"/>
  </joint>
  <!-- end of joint list -->
  <!-- link list -->
  <link name="s_model_palm">
    <visual>
      <geometry>
        <mesh filename="package://robotiq_s_model_visualization/meshes/s-model_articulated/visual/palm.dae"/>
      </geometry>
      <material name="gray">
        <color rgba="0.2 0.2 0.2 1"/>
      </material>
    </visual>
    <collision>
      <geometry>
        <mesh filename="package://robotiq_s_model_visualization/meshes/s-model_articulated/collision/palm.dae"/>
      </geometry>
      <material name="yellow">
        <color rgba="0 1 1 1"/>
      </material>
    </collision>
  </link>
  <link name="s_model_tool0"/>
  <inertial>
    <origin rpy="0 0 0" xyz="0 0 0"/>
    <mass value="1.3"/>
    <inertia ixx="0.006012" ixy="0.000079" ixz="-0.00024" iyy="0.012892" iyz="0" izz="0.002435"/>
  </inertial>
  <!-- end of link list -->
  <!-- joint list -->
  <joint name="s_model_palm_finger_1_joint" type="revolute">
    <parent link="s_model_palm"/>
    <child link="s_model_finger_1_link_0"/>
    <axis xyz="0 1 0"/>
    <origin rpy="0 3.1416 -1.57" xyz="-0.0455 0.0214 0.036"/>
    <limit effort="100" lower="-0.1784" upper="0.192" velocity="100"/>
  </joint>
  <joint name="s_model_palm_finger_2_joint" type="revolute">
    <parent link="s_model_palm"/>
    <child link="s_model_finger_2_link_0"/>
    <axis xyz="0 1 0"/>
    <origin rpy="0 3.1416 -1.57" xyz="-0.0455 0.0214 -0.036"/>
    <limit effort="100" lower="-0.192" upper="0.1784" velocity="100"/>
  </joint>
  <joint name="s_model_palm_finger_middle_joint" type="fixed">
    <parent link="s_model_palm"/>
    <child link="s_model_finger_middle_link_0"/>
    <axis xyz="0 0 1"/>
    <origin rpy="0 0 1.57" xyz="0.0455 0.0214 0"/>
  </joint>
  <joint name="s_model_palm_tool0" type="fixed">
    <parent link="s_model_palm"/>
    <child link="s_model_tool0"/>
    <origin rpy="0 0 1.5707" xyz="0.0 0.0875 0.0"/>
  </joint>
  <!-- end of joint list -->
  <joint name="gripper_joint" type="fixed">
    <parent link="tool0"/>
    <child link="s_model_palm"/>
    <origin rpy="0.0 0.0 -1.570796325" xyz="0.0775 0.0 0.0"/>
  </joint>
  <!-- plug collision model -->
  <!-- gripper plugs  -->
  <link name="plug_collision_model_link_1">
    <!-- TODO values for inertial are not correct -->
    <inertial>
      <mass value="0.2"/>
      <origin xyz="0.0 0.0 0.0"/>
      <inertia ixx="0.002708332" ixy="0.0" ixz="0.0" iyy="0.000708333" iyz="0.0" izz="0.003333332"/>
    </inertial>
    <collision>
      <origin rpy="0.0 0.0 0.0" xyz="0.065 0.065 0.0"/>
      <geometry>
        <box size="0.05 0.10 0.075"/>
      </geometry>
    </collision>
  </link>
  <joint name="plug_collision_model_link_1_joint" type="fixed">
    <origin rpy="0.0 0.0 0.0" xyz="0.0 0.0 0.0"/>
    <child link="plug_collision_model_link_1"/>
    <parent link="ur5_ee_link"/>
  </joint>
  <!-- force torque plug -->
  <link name="plug_collision_model_link_2">
    <!-- TODO values for inertial are not correct -->
    <inertial>
      <mass value="0.2"/>
      <origin xyz="0.0 0.0 0.0"/>
      <inertia ixx="0.002708332" ixy="0.0" ixz="0.0" iyy="0.000708333" iyz="0.0" izz="0.003333332"/>
    </inertial>
    <collision>
      <origin rpy="0.0 0.0 0.0" xyz="0.025 -0.01 0.09"/>
      <geometry>
        <box size="0.03 0.06 0.06"/>
      </geometry>
    </collision>
  </link>
  <joint name="plug_collision_model_link_2_joint" type="fixed">
    <origin rpy="0.0 0.0 0.0" xyz="0.0 0.0 0.0"/>
    <child link="plug_collision_model_link_2"/>
    <parent link="ur5_ee_link"/>
  </joint>
  <link name="world"/>
  <joint name="world_floor_joint" type="fixed">
    <parent link="world"/>
    <child link="floor"/>
    <origin rpy="0.0 0.0 0.0" xyz="0.0 0.0 0.0"/>
  </joint>
  <link name="map"/>
  <joint name="map_world" type="fixed">
    <parent link="world"/>
    <child link="map"/>
    <origin rpy="0.0 0.0 -0.32" xyz="0.9 1.3 0.0"/>
  </joint>
  <joint name="wall_ur5_joint" type="fixed">
    <parent link="ur5_mount"/>
    <child link="ur5_base_link"/>
    <origin rpy="0.0 0.0 1.570796325" xyz="0 0 0.003"/>
  </joint>
</robot>

